<?xml version="1.0"?>
<robot name="minisumo">

  <material name="dark_green"><color rgba="0.0 0.4 0.2 1"/></material>
  <material name="black"><color rgba="0.1 0.1 0.1 1"/></material>
  <material name="yellow"><color rgba="0.9 0.9 0.0 1"/></material>
  <material name="purple"><color rgba="0.5 0.0 0.5 1"/></material>

  <link name="base_link">
    <visual>
      <origin xyz="0 0 0.03" rpy="0 0 0"/>
      <geometry>
        <box size="0.12 0.12 0.06"/>
      </geometry>
      <material name="dark_green"/>
    </visual>
  </link>

  <link name="base_footprint"/>
  <joint name="base_joint" type="fixed">
    <parent link="base_footprint"/>
    <child link="base_link"/>
    <origin xyz="0 0 0" rpy="0 0 0"/>
  </joint>

  <link name="wheel_left">
    <visual>
      <origin xyz="0 0 0" rpy="1.5708 0 0"/>
      <geometry>
        <cylinder radius="0.033" length="0.025"/>
      </geometry>
      <material name="yellow"/>
    </visual>
  </link>

  <joint name="wheel_left_joint" type="continuous">
    <parent link="base_link"/>
    <child link="wheel_left"/>
    <origin xyz="0 0.06 0.033" rpy="0 0 0"/>
    <axis xyz="0 1 0"/>
  </joint>

  <link name="wheel_right">
    <visual>
      <origin xyz="0 0 0" rpy="1.5708 0 0"/>
      <geometry>
        <cylinder radius="0.033" length="0.025"/>
      </geometry>
      <material name="yellow"/>
    </visual>
  </link>

  <joint name="wheel_right_joint" type="continuous">
    <parent link="base_link"/>
    <child link="wheel_right"/>
    <origin xyz="0 -0.06 0.033" rpy="0 0 0"/>
    <axis xyz="0 1 0"/>
  </joint>

</robot>
